Workbook
Name Excel_BuiltIn_Print_Area: '-EVALUACION OCUPACIONAL 1-3'!$A$3:$BG$67

Sheet -EVALUACION OCUPACIONAL 1-3
L1: FORMULARIO DE EVALUACIÓN MÉDICA OCUPACIONAL
B3: A. DATOS DEL ESTABLECIMIENTO - DATOS DEL USUARIO TELEF:
B4: INSTITUCIÓN DEL SISTEMA | Q4: RUC | Z4: CIIU | AC4: ESTABLECIMIENTO /CENTRO DE TRABAJO | AP4: NUMERO DE HISTORIA CLINICA | BB4: NÚMERO DE ARCHIVO
AC5: DEPARTAMENTO DE SALUD OCUPACIONAL | BB5: 1
B6: PRIMER APELLIDO | S6: SEGUNDO APELLIDO | AH6: PRIMER NOMBRE | AR6: SEGUNDO NOMBRE
B9: ATENCIÓN PRIORITARIA | U9: SEXO | Z9: FECHA DE NACIMIENTO | AF9: Edad | AH9: GRUPO SANGUÍNEO | AP9: LATERALIDAD
B10: Embarazada | G10: Persona con Discapacidad | K10: E.Catastrófica | N10: lactancia | R10: Adulto Mayor
U11: hombre | X11: mujer
Z12: año | AC12: mes | AE12: día
B13: NO APLICA
B15: B. MOTIVO DE CONSULTA
B16: Puesto de Trabajo CIUO | J16: AUXILIAR DE LIMPIEZA (9112) / | Y16: Fecha de Atención aaaa/mm/dd
B17: Fecha de Ingreso al trabajo aaaa/mm/dd | AD17: Fecha de Reintegro aaaa/mm/dd | AM17: Fecha del Último día laboral/salida aaaa/mm/dd
B19: INGRESO | O19: PERIÓDICO | AD19: REINTEGRO | AM19: RETIRO | BA19: X
B20: Observación
B22: C. ANTECEDENTES PERSONALES
B23: ANTECEDENTES CLÍNICOS Y QUIRÚRGICOS
B24: Descripción: ANTECEDENTES QUIRURGICOS: NO REFIERE ANTECEDENTES PATOLOGICOS PERSONALES: NO REFIERE ALERGIAS MEDICAMENTOSA Y POR ALIMENTOS: NO REFIERE
B25: ANTECEDENTES FAMILIARES
B26: Descripción:
B27: Condición especial para las atenciónes de urgencia,emergencia,y tratamiento médico (referido por el paciente).
B28: En caso de requerir transfusiones autoriza : | O28: SI | S28: NO | W28: Se encuentra bajo algún tratamiento hormonal | AH28: SI | AL28: ¿Cuál describir? | BE28: NO
BE29: X
B30: ANTECEDENTES GINECO OBSTÉTRICOS
B31: FECHA DE LA ULTIMA MENSTRUACIÓNN aaaa /mm/dd | X31: GESTAS | AB31: PARTOS | AE31: CESÁREAS | AH31: ABORTOS | AL31: MÉTODO DE PLANIFICACION FAMILIAR
AL32: si | AN32: ¿cual? | AV32: no | AZ32: no responde
B33: NO APLICA
B34: EXÁMENES REALIZADOS ¿CUAL? | L34: TIEMPO (años) | U34: Registrar resultado únicamente si interfiere con la actividad laboral y previa autorización del titular
B36: ANTECEDENTES REPRODUCTIVOS MASCULINOS
B37: EXÁMENES REALIZADOS ¿CUAL? | O37: TIEMPO (años) | U37: Registrar resultado únicamente si interfiere con la actividad laboral y previa autorización del titular | AE37: MÉTODO DE PLANIFICACIÓN FAMILIAR
AE38: si | AF38: ¿cual? | AP38: no | AY38: no responde
B39: NO REFIERE
B41: CONSUMO DE SUSTANCIAS | AE41: ESTILO DE VIDA | AO41: CONDICION PREEXISTENTE
N42: TIEMPO DE CONSUMO (meses) | S42: EX CONSUMIDOR | X42: TIEMPO DE ABSTINENCIA (meses) | AB42: NO CONSUME | AE42: ACTIVIDAD FÍSICA | AI42: ¿CUAL? | AL42: TIEMPO | AO42: MEDICACIÓN HABITUAL | AU42: ¿ CUÁL? | BC42: CANTIDAD
B43: TABACO
B44: ALCOHOL
B45: OTRAS: ¿Cuál? __________________________
B46: Observación__________________________
B48: D. ENFERMEDAD O PROBLEMA ACTUAL
B49: Descripción: Al momento de la evaluación, no refiere enfermedad o problema de salud actual. Refiere contar con vacunación contra COVID-19, según las dosis disponibles y recibidas. No presenta sintomatología actual relacionada.
...

Sheet EVALUACION OCUPACIONAL2-3
A1: G. FACTORES DE RIESGO DEL TRABAJO ACTUAL
A2: PUESTO DE TRABAJO | G2: AUXILIAR DE LIMPIEZA (9112) /
A3: ACTIVIDADES IMPORTANTES DENTRO DE LA JORNADA LABORAL | G3: 1 | I3: 2 | K3: 3 | M3: 4 | N3: 5 | O3: 6 | P3: 7
G5: Limpieza y desinfección de áreas asignadas (pisos, baños, pasillos, oficinas y áreas comunes). Barrido, trapeado y secado de superficies. | I5: Recolección y disposición adecuada de residuos. | K5: Manipulación y uso de productos químicos de limpieza. | M5: Uso continuo de herramientas manuales (escobas, trapeadores, baldes, paños). | N5: Permanencia prolongada en bipedestación y desplazamiento constante. | O5: Flexión, extensión y movimientos repetitivos de miembros superiores.
A6: FÍSICO | D6: Temperaturas altas
D7: Temperaturas bajas | G7: X
D8: Radiación Ionizante
D9: Radiación No Ionizante
D10: Ruido | I10: X
D11: Vibración | I11: X
D12: Iluminación
D13: Ventilación
D14: Fluido eléctrico
D15: Otros __________
A16: DE SEGURIDAD | C16: LOCATIVOS | D16: Falta de señalización,aseo, desorden
C17: MECÁNICOS | D17: Atrapamiento entre Máquinas y o superficies
D18: Atrapamiento entre objetos | I18: X
D19: Caída de objetos | I19: X
D20: Caídas al mismo nivel | I20: X
D21: Caídas a diferente nivel | I21: X
D22: Pinchazos | I22: X
D23: Cortes | I23: X
D24: Choques /colisión vehicular
D25: Atropellamientos por vehículos
D26: Proyección de fluidos
D27: Proyección de partículas – fragmentos
D28: Contacto con superficies de trabajos
C29: ELÉCTRICOS | D29: Contacto eléctrico
C30: OTROS | D30: __________
A31: QUÌMICO | D31: Polvos | K31: X
D32: Sólidos | K32: X
D33: Humos
D34: líquidos | K34: X
D35: vapores
D36: Aerosoles
D37: Neblinas | K37: X
D38: Gaseosos
D39: Otros __________
A40: BIOLÓGICO | D40: Virus | M40: X
D41: Hongos | M41: X
...

Sheet EVALUACION OCUPACIONAL 3-3
B1: H. ACTIVIDAD LABORAL/ INCIDENTES/ACCIDENTES / ENFERMEDADES OCUPACIONALES
B2: ANTECEDENTES DE EMPLEOS ANTERIORES Y/O TRABAJO ACTUAL
B3: CENTRO DE TRABAJO | J3: ACTIVIDADES QUE DESEMPEÑABA | W3: TRABAJO | AC3: De los Accidentes de Trabajo y las Enfermedades Profesionales | AK3: CALIFICADO POR INSTITUTO ECUATORIANO DE SEGURIDAD SOCIAL
W4: ANTERIOR | Y4: ACTUAL | AA4: TIEMPO DE TRABAJO | AC4: INCIDENTE | AE4: ACCIDENTE | AH4: ENFERMEDAD PROFESIONAL | AK4: SI | AM4: NO | AO4: FECHA aaaa/mm/dd | AR4: ESPECIFICAR | BE4: Observaciónes
B8: I. ACTIVIDADES EXTRA LABORALES
A9: TIPO DE ACTIVIDAD | BA9: ( FECHA) aaaa/mm/dd
B10: NIEGA
B13: J. RESULTADOS DE EXÁMENES GENERALES Y ESPECÍFICOS DE ACUERDO AL RIESGO Y PUESTO DE TRABAJO (IMAGEN, LABORATORIO Y OTROS)
B14: NOMBRE DEL EXAMEN | M14: FECHA aaaa/mm/dd | T14: RESULTADOS
B15: BIOMETRIA HEMATICA
B16: QUIMICA SANGUINEA
B17: RX DE LUMBAR AP Y LATERAL
A18: EMO / COPROLOGICO
B19: VDRL
B20: OBSERVACIONES:
B22: K. DIAGNÓSTICO PRE:PRESUNTIVO DEF: DEFINITIVO
B23: CIE-10 | Q23: Descripción | BE23: PRE | BJ23: DEF
B24: 1. Z010 | Q24: EXAMEN DE SALUD OCUPACIONAL | BJ24: X
B25: 2, Z000 | Q25: EXAMEN MEDICO GENERAL | BJ25: X
B26: 3
B27: L. APTITUD MÉDICA PARA EL TRABAJO
B28: APTO | R28: APTO EN OBSERVACIÓN | AG28: APTO CON LIMITACIONES | AU28: NO APTO | BB28: X
B29: Se realiza evaluación médica ocupacional de retiro al colaborador que desempeñó funciones operativas como auxiliar de limpieza, considerando las actividades realizadas y los riesgos laborales a los que estuvo expuesto. Se recomienda mantener las medidas de autocuidado. Los hallazgos clínicos y las recomendaciones específicas se consignan de acuerdo con los resultados de la evaluación de retiro.
B30: OBSERVACIONES:
B32: M. RECOMENDACIONES Y/O TRATAMIENTO
B33: Descripción:
B34: RECOMENDACIONES GENERALES: Mantener una alimentación equilibrada, adecuada hidratación y hábitos de sueño saludables. Realizar actividad física regularmente, de acuerdo con su condición de salud. Acudir a controles médicos preventivos y mantener actualizado su esquema de vacunación. Informar al Departamento de Salud Ocupacional sobre cualquier cambio relevante en su estado de salud. RECOMENDACIONES LABORALES: Utilizar correctamente los EPP correspondientes a cada actividad y cumplir los procedimientos de trabajo seguro. Realizar trabajos en un solo nivel conforme a la aptitud médica, capacitación y autorización correspondientes, utilizando protección contra caídas cuando aplique. Cumplir las medidas de seguridad establecidas y realizar las actividades bajo supervisión de su jefe inmediato. Aplicar técnicas adecuadas de manipulación de cargas y mantener posturas ergonómicas durante las labores de limpieza. Manipular los productos químicos conforme a sus instrucciones de seguridad, evitando mezclas no autorizadas. Mantener el área de trabajo ordenada, señalizar superficies húmedas y reportar oportunamente cualquier condición insegura.
B35: N.RETIRO (evaluación)
B36: SE REALIZA LA EVALUACIÓN | W36: SI | AI36: NO
B37: LA CONDICIÓN DE SALUD ESTA RELACIONADA CON EL TRABAJO | W37: SI | AI37: NO
B38: Observación:
B39: O. DATOS DEL PROFESIONAL | AU39: P. FIRMA DEL TRABAJADOR
B40: NOMBRES Y APELLIDOS DEL PROFESIONAL | K40: IVONNE ASTRID CARVAJAL PILLIZA | U40: CÓDIGO MEDICO | AD40: 2673649 | AH40: FIRMA Y SELLO

Sheet CERTIFICADO
I1: CERTIFICADO - EVALUACIÓN MÉDICA OCUPACIONAL
A2: =IF('-EVALUACION OCUPACIONAL 1-3'!B3="","",'-EVALUACION OCUPACIONAL 1-3'!B3) -> A. DATOS DEL ESTABLECIMIENTO - DATOS DEL USUARIO TELEF:
A3: INSTITUCIÓN DEL SISTEMA | L3: RUC | R3: CIIU | V3: ESTABLECIMIENTO /CENTRO DE TRABAJO | AC3: CÉDULA / N.º H.C. | AI3: NÚMERO DE ARCHIVO
A4: =IF('-EVALUACION OCUPACIONAL 1-3'!B5="","",'-EVALUACION OCUPACIONAL 1-3'!B5) | L4: =IF('-EVALUACION OCUPACIONAL 1-3'!Q5="","",'-EVALUACION OCUPACIONAL 1-3'!Q5) | R4: =IF('-EVALUACION OCUPACIONAL 1-3'!Z5="","",'-EVALUACION OCUPACIONAL 1-3'!Z5) | V4: =IF('-EVALUACION OCUPACIONAL 1-3'!AC5="","",'-EVALUACION OCUPACIONAL 1-3'!AC5) -> DEPARTAMENTO DE SALUD OCUPACIONAL | AC4: =IF('-EVALUACION OCUPACIONAL 1-3'!AP5="","",'-EVALUACION OCUPACIONAL 1-3'!AP5&"") | AI4: =IF('-EVALUACION OCUPACIONAL 1-3'!BB5="","",'-EVALUACION OCUPACIONAL 1-3'!BB5) -> 1
A5: PRIMER APELLIDO | J5: SEGUNDO APELLIDO | Q5: PRIMER NOMBRE | X5: SEGUNDO NOMBRE | AD5: SEXO | AG5: PUESTO DE TRABAJO (CIUO)
A6: =IF('-EVALUACION OCUPACIONAL 1-3'!B8="","",'-EVALUACION OCUPACIONAL 1-3'!B8) | J6: =IF('-EVALUACION OCUPACIONAL 1-3'!S8="","",'-EVALUACION OCUPACIONAL 1-3'!S8) | Q6: =IF('-EVALUACION OCUPACIONAL 1-3'!AH8="","",'-EVALUACION OCUPACIONAL 1-3'!AH8) | X6: =IF('-EVALUACION OCUPACIONAL 1-3'!AR8="","",'-EVALUACION OCUPACIONAL 1-3'!AR8) | AD6: =IF(AND(UPPER(TRIM('-EVALUACION OCUPACIONAL 1-3'!U13))="X",UPPER(TRIM('-EVALUACION OCUPACIONAL 1-3'!X13))="X"),"REVISAR SEXO",IF(UPPER(TRIM('-EVALUACION OCUPACIONAL 1-3'!U13))="X","masculino",IF(UPPER(TRIM('-EVALUACION OCUPACIONAL 1-3'!X13))="X","femenino",""))) | AG6: =IF('-EVALUACION OCUPACIONAL 1-3'!J16="","",'-EVALUACION OCUPACIONAL 1-3'!J16) -> AUXILIAR DE LIMPIEZA (9112) /
A7: B. DATOS GENERALES
B9: FECHA DE EMISIÓN: | K9: =IF(ISNUMBER('-EVALUACION OCUPACIONAL 1-3'!AH16),YEAR('-EVALUACION OCUPACIONAL 1-3'!AH16),"") | M9: =IF(ISNUMBER('-EVALUACION OCUPACIONAL 1-3'!AH16),LEFT(TEXT('-EVALUACION OCUPACIONAL 1-3'!AH16,"mm"),1),"") | N9: =IF(ISNUMBER('-EVALUACION OCUPACIONAL 1-3'!AH16),RIGHT(TEXT('-EVALUACION OCUPACIONAL 1-3'!AH16,"mm"),1),"") | O9: =IF(ISNUMBER('-EVALUACION OCUPACIONAL 1-3'!AH16),LEFT(TEXT('-EVALUACION OCUPACIONAL 1-3'!AH16,"dd"),1),"") | P9: =IF(ISNUMBER('-EVALUACION OCUPACIONAL 1-3'!AH16),RIGHT(TEXT('-EVALUACION OCUPACIONAL 1-3'!AH16,"dd"),1),"")
K10: aaaa | M10: mm | O10: dd
B11: EVALUACIÓN: | I11: INGRESO | L11: =IF('-EVALUACION OCUPACIONAL 1-3'!G19="","",'-EVALUACION OCUPACIONAL 1-3'!G19) | P11: PERIÓDICO | U11: =IF('-EVALUACION OCUPACIONAL 1-3'!Z19="","",'-EVALUACION OCUPACIONAL 1-3'!Z19) | W11: REINTEGRO | AC11: =IF('-EVALUACION OCUPACIONAL 1-3'!AI19="","",'-EVALUACION OCUPACIONAL 1-3'!AI19) | AF11: RETIRO | AI11: =IF('-EVALUACION OCUPACIONAL 1-3'!BA19="","",'-EVALUACION OCUPACIONAL 1-3'!BA19) -> X
A14: C. APTITUD MÉDICA PARA EL TRABAJO
A15: Después de la valoración médica ocupacional se certifica que la persona en mención, es calificada como:
A16: APTO | I16: =IF('EVALUACION OCUPACIONAL 3-3'!P28="","",'EVALUACION OCUPACIONAL 3-3'!P28) | J16: APTO EN OBSERVACIÓN | S16: =IF('EVALUACION OCUPACIONAL 3-3'!AE28="","",'EVALUACION OCUPACIONAL 3-3'!AE28) | U16: APTO CON LIMITACIONES | AC16: =IF('EVALUACION OCUPACIONAL 3-3'!AS28="","",'EVALUACION OCUPACIONAL 3-3'!AS28) | AE16: NO APTO | AK16: =IF('EVALUACION OCUPACIONAL 3-3'!BB28="","",'EVALUACION OCUPACIONAL 3-3'!BB28) -> X
A17: ="DETALLE DE OBSERVACIONES: "&IF('EVALUACION OCUPACIONAL 3-3'!B29="","",'EVALUACION OCUPACIONAL 3-3'!B29) -> DETALLE DE OBSERVACIONES: Se realiza evaluación médica ocupacional de retiro al colaborador que desempeñó funciones operativas como auxiliar de limpieza, considerando las actividades realizadas y los riesgos laborales a los que estuvo expuesto. Se recomienda mantener las medidas de autocuidado. Los hallazgos clínicos y las recomendaciones específicas se consignan de acuerdo con los resultados de la evaluación de retiro.
A18: DETALLE DE OBSERVACIONES:
A19: D. RECOMENDACIONES/OBSERVACIONES
A20: Descripción
A21: =IF('EVALUACION OCUPACIONAL 3-3'!B34="","",'EVALUACION OCUPACIONAL 3-3'!B34) -> RECOMENDACIONES GENERALES: Mantener una alimentación equilibrada, adecuada hidratación y hábitos de sueño saludables. Realizar actividad física regularmente, de acuerdo con su condición de salud. Acudir a controles médicos preventivos y mantener actualizado su esquema de vacunación. Informar al Departamento de Salud Ocupacional sobre cualquier cambio relevante en su estado de salud. RECOMENDACIONES LABORALES: Utilizar correctamente los EPP correspondientes a cada actividad y cumplir los procedimientos de trabajo seguro. Realizar trabajos en un solo nivel conforme a la aptitud médica, capacitación y autorización correspondientes, utilizando protección contra caídas cuando aplique. Cumplir las medidas de seguridad establecidas y realizar las actividades bajo supervisión de su jefe inmediato. Aplicar técnicas adecuadas de manipulación de cargas y mantener posturas ergonómicas durante las labores de limpieza. Manipular los productos químicos conforme a sus instrucciones de seguridad, evitando mezclas no autorizadas. Mantener el área de trabajo ordenada, señalizar superficies húmedas y reportar oportunamente cualquier condición insegura.
A22: Con este documento certifico que el trabajador se ha sometido a la evaluación médica requerida para (el ingreso /la ejecución/ el reingreso y retiro) al puesto laboral y se le ha informado sobre los riesgos relacionados con el trabajo emitiendo recomendaciones relacionadas con su estado de salud.
A24: La presente certificación se expide con base en el formulario de Evaluación Ocupacional , el cual tiene carácter de confidencial.
A26: E. DATOS DEL PROFESIONAL | AD26: F. FIRMA DEL USUARIO
A27: NOMBRE Y APELLIDO | E27: IVONNE ASTRID CARVAJAL PILLIZA | L27: CÓDIGO MEDICO | O27: 2673649 | T27: FIRMA Y SELLO
